[2024-02-16 01:46:39,771: INFO: utils: Note: NumExpr detected 20 cores but "NUMEXPR_MAX_THREADS" not set, so enforcing safe limit of 8.]
[2024-02-16 01:46:39,771: INFO: utils: NumExpr defaulting to 8 threads.]
[2024-02-16 01:46:44,128: WARNING: module_wrapper: From C:\ProgramData\Anaconda3\lib\site-packages\keras\src\losses.py:2976: The name tf.losses.sparse_softmax_cross_entropy is deprecated. Please use tf.compat.v1.losses.sparse_softmax_cross_entropy instead.
]
[2024-02-16 01:46:44,373: INFO: main: >>>>>>>>>> stage Data Ingestion Stage started <<<<<<<<<<]
[2024-02-16 01:46:44,377: INFO: common: yaml file: config\config.yaml loaded successfully]
[2024-02-16 01:46:44,377: INFO: common: yaml file: config\params.yaml loaded successfully]
[2024-02-16 01:46:44,377: INFO: common: Created directory at: artifacts]
[2024-02-16 01:46:44,377: INFO: common: Created directory at: data]
[2024-02-16 01:46:44,377: INFO: data_ingestion: Raw data path is - data]
[2024-02-16 01:46:44,377: INFO: main: >>>>>>>>>> stage Data Ingestion Stage completed <<<<<<<<<<

X==========X]
[2024-02-16 01:46:44,377: INFO: main: >>>>>>>>>> stage Data Validation stage started <<<<<<<<<<]
[2024-02-16 01:46:44,381: INFO: common: yaml file: config\config.yaml loaded successfully]
[2024-02-16 01:46:44,381: INFO: common: yaml file: config\params.yaml loaded successfully]
[2024-02-16 01:46:44,381: INFO: common: Created directory at: artifacts]
[2024-02-16 01:46:44,381: INFO: common: Created directory at: artifacts/ data_validation]
[2024-02-16 01:46:44,381: INFO: main: >>>>>>>>>> stage Data Validation stage completed <<<<<<<<<<

X==========X]
[2024-02-16 01:46:44,381: INFO: main: >>>>>>>>>> stage Data transformation stage started <<<<<<<<<<]
[2024-02-16 01:46:44,385: INFO: common: yaml file: config\config.yaml loaded successfully]
[2024-02-16 01:46:44,385: INFO: common: yaml file: config\params.yaml loaded successfully]
[2024-02-16 01:46:44,385: INFO: common: Created directory at: artifacts]
[2024-02-16 01:46:44,385: INFO: common: Created directory at: artifacts/data_transformation]
[2024-02-16 01:46:44,385: ERROR: main: 'DataTransformation' object has no attribute 'get_text_data']
Traceback (most recent call last):
  File "C:\Master's In Mechatronics\Practice\NLP\new_successive_word_suggestion\main.py", line 32, in <module>
    data_transformation.main()
  File "C:\Master's In Mechatronics\Practice\NLP\new_successive_word_suggestion\src\pipeline\stage_03_data_transformation.py", line 15, in main
    text_data = data_transformation.get_text_data()
AttributeError: 'DataTransformation' object has no attribute 'get_text_data'
