[2024-02-16 02:30:11,889: INFO: utils: Note: NumExpr detected 20 cores but "NUMEXPR_MAX_THREADS" not set, so enforcing safe limit of 8.]
[2024-02-16 02:30:11,890: INFO: utils: NumExpr defaulting to 8 threads.]
[2024-02-16 02:30:16,834: WARNING: module_wrapper: From C:\ProgramData\Anaconda3\lib\site-packages\keras\src\losses.py:2976: The name tf.losses.sparse_softmax_cross_entropy is deprecated. Please use tf.compat.v1.losses.sparse_softmax_cross_entropy instead.
]
[2024-02-16 02:30:17,501: INFO: main: >>>>>>>>>> stage Data Ingestion Stage started <<<<<<<<<<]
[2024-02-16 02:30:17,504: INFO: common: yaml file: config\config.yaml loaded successfully]
[2024-02-16 02:30:17,505: INFO: common: yaml file: config\params.yaml loaded successfully]
[2024-02-16 02:30:17,506: INFO: common: Created directory at: artifacts]
[2024-02-16 02:30:17,507: INFO: common: Created directory at: data]
[2024-02-16 02:30:17,507: INFO: data_ingestion: Raw data path is - data]
[2024-02-16 02:30:17,508: INFO: main: >>>>>>>>>> stage Data Ingestion Stage completed <<<<<<<<<<

X==========X]
[2024-02-16 02:30:17,508: INFO: main: >>>>>>>>>> stage Data Validation stage started <<<<<<<<<<]
[2024-02-16 02:30:17,510: INFO: common: yaml file: config\config.yaml loaded successfully]
[2024-02-16 02:30:17,511: INFO: common: yaml file: config\params.yaml loaded successfully]
[2024-02-16 02:30:17,512: INFO: common: Created directory at: artifacts]
[2024-02-16 02:30:17,513: INFO: common: Created directory at: artifacts/ data_validation]
[2024-02-16 02:30:17,514: INFO: main: >>>>>>>>>> stage Data Validation stage completed <<<<<<<<<<

X==========X]
[2024-02-16 02:30:17,515: INFO: main: >>>>>>>>>> stage Data transformation stage started <<<<<<<<<<]
[2024-02-16 02:30:17,517: INFO: common: yaml file: config\config.yaml loaded successfully]
[2024-02-16 02:30:17,518: INFO: common: yaml file: config\params.yaml loaded successfully]
[2024-02-16 02:30:17,519: INFO: common: Created directory at: artifacts]
[2024-02-16 02:30:17,519: INFO: common: Created directory at: artifacts/data_transformation]
[2024-02-16 02:30:17,525: INFO: data_transformation: Loaded text data from ******* Sherlock Holmes.txt ******* succcessfully]
[2024-02-16 02:30:17,526: ERROR: main: cannot assign to field 'tokenizer_name']
Traceback (most recent call last):
  File "C:\Master's In Mechatronics\Practice\NLP\new_successive_word_suggestion\main.py", line 32, in <module>
    data_transformation.main()
  File "C:\Master's In Mechatronics\Practice\NLP\new_successive_word_suggestion\src\pipeline\stage_03_data_transformation.py", line 18, in main
    text_data = data_transformation.get_text_data()
  File "C:\Master's In Mechatronics\Practice\NLP\new_successive_word_suggestion\src\components\data_transformation.py", line 20, in get_text_data
    self.config.tokenizer_name = str(filename)
  File "<string>", line 4, in __setattr__
dataclasses.FrozenInstanceError: cannot assign to field 'tokenizer_name'
